<?xml version="1.0" ?>
<robot name="m2wr" xmlns:xacro="https://www.ros.org/wiki/xacro" >
    

 <xacro:include filename="$(find surveillance_fsm_robot)/urdf/materials.xacro" />
 <xacro:include filename="$(find surveillance_fsm_robot)/urdf/m2wr_arm2.gazebo" />

 <xacro:macro name="cylinder_inertia" params="mass r l"> 
    <inertia ixx="${mass*(3*r*r+l*l)/12}" ixy = "0" ixz = "0"
                iyy="${mass*(3*r*r+l*l)/12}" iyz = "0" izz="${mass*(r*r)/2}" /> 
 </xacro:macro>

    	<xacro:property name="length_wheel" value="0.04" />
	<xacro:property name="radius_wheel" value="0.1" />

	<xacro:macro name="default_inertial" params="mass">
               <inertial>
                       <mass value="${mass}" />
                       <origin rpy="0 1.5707 1.5707" xyz="0 0 0"/>
                       <inertia ixx="0.000526666666667" ixy="0" ixz="0" iyy="0.000526666666667" iyz="0" izz="0.001"/>
               </inertial>
	</xacro:macro>

    <xacro:macro name="wheel_geometry">
		<geometry>
       			<cylinder length="${length_wheel}" radius="${radius_wheel}"/>
     	</geometry>
	</xacro:macro>
	


	  <link name="base_link">
    <!-- pose and inertial -->
    <pose>0 0 0.1 0 0 0</pose>
    <inertial>
      <mass value="5"/>
      <origin rpy="0 0 0" xyz="0 0 0.1"/>
      <inertia ixx="0.0395416666667" ixy="0" ixz="0" iyy="0.106208333333" iyz="0" izz="0.106208333333"/>
    </inertial>
    <!-- body -->
    <collision name="collision_chassis">
      <geometry>
        <box size="0.5 0.3 0.07"/>
      </geometry>
    </collision>
    <visual>
      <origin rpy="0 0 0" xyz="0 0 0"/>
      <geometry>
        <box size="0.5 0.3 0.07"/>
      </geometry>
      <material name="red"/>
    </visual>


  </link>
   <link name="link_right_wheel">
    <xacro:default_inertial mass="0.2"/>
    <collision name="link_right_wheel_collision">
      <origin rpy="0 1.5707 1.5707" xyz="0 0 0"/>
      <xacro:wheel_geometry />
    </collision>
    <visual name="link_right_wheel_visual">
      <origin rpy="0 1.5707 1.5707" xyz="0 0 0"/>
      <xacro:wheel_geometry />
      <material name="black"/>
    </visual>
  </link>
  
  <link name="link_right_wheel_back">
    <xacro:default_inertial mass="0.2"/>
    <collision name="link_right_wheel_collision_back">
      <origin rpy="0 1.5707 1.5707" xyz="0 0 0"/>
      <xacro:wheel_geometry />
    </collision>
    <visual name="link_right_wheel_visual_back">
      <origin rpy="0 1.5707 1.5707" xyz="0 0 0"/>
      <xacro:wheel_geometry />
      <material name="black"/>
    </visual>
  </link>

   <link name="link_left_wheel">
    <xacro:default_inertial mass="0.2"/>
    <collision name="link_left_wheel_collision">
      <origin rpy="0 1.5707 1.5707" xyz="0 0 0"/>
      <xacro:wheel_geometry />
    </collision>
    <visual name="link_left_wheel_visual">
      <origin rpy="0 1.5707 1.5707" xyz="0 0 0"/>
      <xacro:wheel_geometry />
      <material name="black"/>
    </visual>
  </link>
  
     <link name="link_left_wheel_back">
    <xacro:default_inertial mass="0.2"/>
    <collision name="link_left_wheel_collision_back">
      <origin rpy="0 1.5707 1.5707" xyz="0 0 0"/>
      <xacro:wheel_geometry />
    </collision>
    <visual name="link_left_wheel_visual_back">
      <origin rpy="0 1.5707 1.5707" xyz="0 0 0"/>
      <xacro:wheel_geometry />
      <material name="black"/>
    </visual>
  </link>


  <joint name="joint_right_wheel" type="continuous">
    <origin rpy="0 0 0" xyz="0.2 -0.17 0"/>
    <child link="link_right_wheel"/>
    <parent link="base_link"/>
    <axis rpy="0 0 0" xyz="0 1 0"/>
    <limit effort="10000" velocity="1000"/>
    <joint_properties damping="1.0" friction="1.0"/>
  </joint>
  
    <joint name="joint_right_wheel_back" type="continuous">
    <origin rpy="0 0 0" xyz="-0.2 -0.17 0"/>
    <child link="link_right_wheel_back"/>
    <parent link="base_link"/>
    <axis rpy="0 0 0" xyz="0 1 0"/>
    <limit effort="10000" velocity="1000"/>
    <joint_properties damping="1.0" friction="1.0"/>
  </joint>
  
  
  <joint name="joint_left_wheel" type="continuous">
    <origin rpy="0 0 0" xyz="0.2 0.17 0"/>
    <child link="link_left_wheel"/>
    <parent link="base_link"/>
    <axis rpy="0 0 0" xyz="0 1 0"/>
    <limit effort="10000" velocity="1000"/>
    <joint_properties damping="1.0" friction="1.0"/>
  </joint>
  
  <joint name="joint_left_wheel_back" type="continuous">
    <origin rpy="0 0 0" xyz="-0.2 0.17 0"/>
    <child link="link_left_wheel_back"/>
    <parent link="base_link"/>
    <axis rpy="0 0 0" xyz="0 1 0"/>
    <limit effort="10000" velocity="1000"/>
    <joint_properties damping="1.0" friction="1.0"/>
  </joint>


   <link name="laser">
    <inertial>
      <origin xyz="0 0 0" rpy="0 0 0" />
      <mass value="1" />
      <xacro:cylinder_inertia mass="1" r="0.05" l="0.1" />
    </inertial>

    <visual>
      <origin xyz="0 0 0" rpy="0 0 0" />
      <geometry>
        <cylinder radius="0.05" length="0.1"/>
      </geometry>
      <material name="white" />
    </visual>

    <collision>
      <origin xyz="0 0 0" rpy="0 0 0"/>
      <geometry>
        <cylinder radius="0.05" length="0.1"/>
      </geometry>
    </collision>
  </link>

  <joint name="joint_laser" type="fixed">
    <origin xyz="0.3 0 0.05" rpy="0 0 0"/>
    <parent link="base_link"/>
    <child link="laser"/>
  </joint>


<!--arm definition -->

  <link name="arm_base_link">
  	<inertial>
  		<mass value="0.1"/>
  		<origin xyz="0 0 0" rpy="0 0 0" />
  		<inertia ixx="0.0" ixy="0" ixz="0" iyy="0.0" iyz="0" izz="0.0"/>
  	</inertial>
  	<collision>
  	  <origin xyz="0 0 0" rpy="0 0 0"/>
      <geometry>
        <box size="0.1 0.1 0.1"/>
      </geometry>
  	</collision>
  	<visual>
  	  <origin xyz="0 0 0" rpy="0 0 0"/>
      <geometry>
        <box size="0.1 0.1 0.1"/>
      </geometry>
      <material name="white" />
  	</visual>
  </link>

  <joint name="arm_base_to_base" type="fixed">
  	<origin rpy="0 0 0" xyz="0.05 0 0.085"/>
  	<parent link="base_link"/>
  	<child link="arm_base_link"/>
  </joint>


  <link name="arm_link_01">
  	<inertial>
  		<mass value="0.0025"/>
  		<origin xyz="0 0 0" rpy="0 0 0" />
  		<inertia ixx="0.0" ixy="0" ixz="0" iyy="0.0" iyz="0" izz="0.0"/>
  	</inertial>
  	<collision>
  	  <origin xyz="0 0 0" rpy="0 0 0"/>
      <geometry>
        <cylinder radius="0.04" length="0.08"/>
      </geometry>
  	</collision>
  	<visual>
  	  <origin xyz="0 0 0" rpy="0 0 0"/>
      <geometry>
        <cylinder radius="0.04" length="0.08"/>
      </geometry>
      <material name="white" />
  	</visual>
  </link>

  <joint name="arm_joint_01" type="revolute">
  	<axis xyz="0 0 1"/>
  	<limit effort="1000.0" lower="-3.14" upper="3.14" velocity="0.2"/>
  	<origin rpy="0 0 0" xyz="0 0 0.09"/>
  	<parent link="arm_base_link"/>
  	<child link="arm_link_01"/>
  </joint>


    <link name="arm_link_02">
  	<inertial>
  		<mass value="0.0025"/>
  		<origin xyz="0 0 0" rpy="0 0 0" />
  		<inertia ixx="0.0" ixy="0" ixz="0" iyy="0.0" iyz="0" izz="0.0"/>
  	</inertial>
  	<collision>
  	  <origin xyz="0 0 0.04" rpy="0 0 0"/>
      <geometry>
        <cylinder radius="0.04" length="0.08"/>
      </geometry>
  	</collision>
  	<visual>
  	  <origin xyz="0 0 0.04" rpy="0 0 0"/>
      <geometry>
        <cylinder radius="0.04" length="0.08"/>
      </geometry>
      <material name="white" />
  	</visual>
  </link>

  <joint name="arm_joint_02" type="revolute">
  	<axis xyz="1 0 0"/>
  	<limit effort="1000.0" lower="-1.8" upper="1.8" velocity="0.2"/>
  	<origin rpy="0 0 0" xyz="0 0 0.04"/>
  	<parent link="arm_link_01"/>
  	<child link="arm_link_02"/>
  </joint>

      <link name="arm_link_03">
  	<inertial>
  		<mass value="0.0025"/>
  		<origin xyz="0 0 0" rpy="0 0 0" />
  		<inertia ixx="0.0" ixy="0" ixz="0" iyy="0.0" iyz="0" izz="0.0"/>
  	</inertial>
  	<collision>
  	  <origin xyz="0 0 0.04" rpy="0 0 0"/>
      <geometry>
        <cylinder radius="0.04" length="0.08"/>
      </geometry>
  	</collision>
  	<visual>
  	  <origin xyz="0 0 0.04" rpy="0 0 0"/>
      <geometry>
        <cylinder radius="0.04" length="0.08"/>
      </geometry>
      <material name="white" />
  	</visual>
  </link>

  <joint name="arm_joint_03" type="revolute">
  	<axis xyz="1 0 0"/>
  	<limit effort="1000.0" lower="-1.8" upper="1.8" velocity="0.2"/>
  	<origin rpy="0 0 0" xyz="0 0 0.08"/>
  	<parent link="arm_link_02"/>
  	<child link="arm_link_03"/>
  </joint>


  <!-- Camera -->
  <link name="camera_link">
    <collision>
      <origin xyz="0 0 0.025" rpy="0 0 0"/>
      <geometry>
        <box size="0.02 0.02 0.02"/>
      </geometry>
    </collision>

    <visual>
      <origin xyz="0 0 0.025" rpy="0 0 0"/>
      <geometry>
    <box size="0.02 0.02 0.02"/>
      </geometry>
      <material name="white"/>
    </visual>

    <inertial>
      <mass value="0" />
      <origin xyz="0 0 0" rpy="0 0 0"/>
      <inertia ixx="0" ixy="0" ixz="0" iyy="0" iyz="0" izz="0" />
    </inertial>
  </link>

  <joint name="camera_joint" type="fixed">
    <axis xyz="0 0 0" />
    <origin xyz="0 0.0 0.07" rpy="0 0 0"/>
    <parent link="arm_link_03"/>
    <child link="camera_link"/>
  </joint>





<transmission name="arm_joint_01_trans">
	<type>transmission_interface/SimpleTransmission</type>
	<joint name="arm_joint_01">
		<hardwareInterface>hardware_interface/EffortJointInterface</hardwareInterface>
	</joint>
	<actuator name="motor1">
		<hardwareInterface>hardware_interface/EffortJointInterface</hardwareInterface>
		<mechanicalInterface>1</mechanicalInterface>
	</actuator>
</transmission>

<transmission name="arm_joint_02_trans">
	<type>transmission_interface/SimpleTransmission</type>
	<joint name="arm_joint_02">
		<hardwareInterface>hardware_interface/EffortJointInterface</hardwareInterface>
	</joint>
	<actuator name="motor2">
		<hardwareInterface>hardware_interface/EffortJointInterface</hardwareInterface>
		<mechanicalInterface>1</mechanicalInterface>
	</actuator>
</transmission>

<transmission name="arm_joint_03_trans">
	<type>transmission_interface/SimpleTransmission</type>
	<joint name="arm_joint_03">
		<hardwareInterface>hardware_interface/EffortJointInterface</hardwareInterface>
	</joint>
	<actuator name="motor3">
		<hardwareInterface>hardware_interface/EffortJointInterface</hardwareInterface>
		<mechanicalInterface>1</mechanicalInterface>
	</actuator>
</transmission>




</robot>
